Workbook

Sheet casesDDM
A1: scen | B1: origin | C1: rule | D1: condition | E1: question | F1: character count | H1: prob(yes) | I1: medianRT
A2: shoe | B2: A friend entered Mary's house wearing shoes and dirtied the carpets. | C2: To keep her house clean, Mary established the rule: "No one may wear shoes in the house". | D2: core | E2: A guest wears stilettos and the carpets get pretty dirty. | F2: =LEN(E2) -> 57 | H2: 0.92 | I2: 1498
A3: shoe | B3: A friend entered Mary's house wearing shoes and dirtied the carpets. | C3: To keep her house clean, Mary established the rule: "No one may wear shoes in the house". | D3: core | E3: A guest wears wet deck shoes and dirties the floors. | F3: =LEN(E3) -> 52 | H3: 1 | I3: 1095
A4: shoe | B4: A friend entered Mary's house wearing shoes and dirtied the carpets. | C4: To keep her house clean, Mary established the rule: "No one may wear shoes in the house". | D4: core | E4: A guest wears muddy sneakers and dirties the carpets. | F4: =LEN(E4) -> 53 | H4: 1 | I4: 829
A5: shoe | B5: A friend entered Mary's house wearing shoes and dirtied the carpets. | C5: To keep her house clean, Mary established the rule: "No one may wear shoes in the house". | D5: over | E5: A guest wears brand new shoes and keeps the floor clean. | F5: =LEN(E5) -> 56 | H5: 0.82 | I5: 1183
A6: shoe | B6: A friend entered Mary's house wearing shoes and dirtied the carpets. | C6: To keep her house clean, Mary established the rule: "No one may wear shoes in the house". | D6: over | E6: A guest wears clean stilettos and keeps the carpet clean. | F6: =LEN(E6) -> 57 | H6: 0.73 | I6: 1436
A7: shoe | B7: A friend entered Mary's house wearing shoes and dirtied the carpets. | C7: To keep her house clean, Mary established the rule: "No one may wear shoes in the house". | D7: over | E7: A guest wears his new sneakers and the floor stays clean. | F7: =LEN(E7) -> 57 | H7: 0.88 | I7: 1201
A8: shoe | B8: A friend entered Mary's house wearing shoes and dirtied the carpets. | C8: To keep her house clean, Mary established the rule: "No one may wear shoes in the house". | D8: under | E8: A guest walks around barefoot and dirties the carpets. | F8: =LEN(E8) -> 54 | H8: 0.11 | I8: 1220
A9: shoe | B9: A friend entered Mary's house wearing shoes and dirtied the carpets. | C9: To keep her house clean, Mary established the rule: "No one may wear shoes in the house". | D9: under | E9: A guest walks in with muddy socks and dirties the floor. | F9: =LEN(E9) -> 56 | H9: 0.31 | I9: 1566
A10: shoe | B10: A friend entered Mary's house wearing shoes and dirtied the carpets. | C10: To keep her house clean, Mary established the rule: "No one may wear shoes in the house". | D10: under | E10: A barefoot guest has a bleeding toe and stains the carpets. | F10: =LEN(E10) -> 59 | H10: 0.12 | I10: 1482
A11: shoe | B11: A friend entered Mary's house wearing shoes and dirtied the carpets. | C11: To keep her house clean, Mary established the rule: "No one may wear shoes in the house". | D11: off | E11: A guest walks around barefoot and keeps the carpet clean. | F11: =LEN(E11) -> 57 | H11: 0 | I11: 1817
A12: shoe | B12: A friend entered Mary's house wearing shoes and dirtied the carpets. | C12: To keep her house clean, Mary established the rule: "No one may wear shoes in the house". | D12: off | E12: A guest walks around in socks and keeps the floor clean. | F12: =LEN(E12) -> 56 | H12: 0.08 | I12: 1674
A13: shoe | B13: A friend entered Mary's house wearing shoes and dirtied the carpets. | C13: To keep her house clean, Mary established the rule: "No one may wear shoes in the house". | D13: off | E13: A guest walks around barefoot and the floor stays clean. | F13: =LEN(E13) -> 56 | H13: 0.08 | I13: 1391
... A85: auth | B85: A careless member of the public caused an accident in a scientific laboratory. | C85: To avoid accidents, the director of a scientific laboratory issued a rule: "Access for Laboratory Personnel Only". | D85: under | E85: A lab member spends the night sleeping on fragile lab equipment. | F85: =LEN(E85) -> 64 | H85: 0.4 | I85: 1663
A86: drin | B86: Drunk drivers pose a serious risk to other road users. | C86: To reduce traffic accidents, a zero tolerance law is passed: "Driving with any trace of alcohol is strictly forbidden". | D86: off | E86: A sober man rides his motorcycle home after playing board games. | F86: =LEN(E86) -> 64
A87: drin | B87: Drunk drivers pose a serious risk to other road users. | C87: To reduce traffic accidents, a zero tolerance law is passed: "Driving with any trace of alcohol is strictly forbidden". | D87: off | E87: A woman drives home after drinking soda at the movie theater. | F87: =LEN(E87) -> 61
A88: drin | B88: Drunk drivers pose a serious risk to other road users. | C88: To reduce traffic accidents, a zero tolerance law is passed: "Driving with any trace of alcohol is strictly forbidden". | D88: off | E88: A sober man re-parks his car in the cul-de-sac to let a guest out. | F88: =LEN(E88) -> 66
A89: drin | B89: Drunk drivers pose a serious risk to other road users. | C89: To reduce traffic accidents, a zero tolerance law is passed: "Driving with any trace of alcohol is strictly forbidden". | D89: core | E89: A young man drives home after drinking heavily at a music festival. | F89: =LEN(E89) -> 68
A90: drin | B90: Drunk drivers pose a serious risk to other road users. | C90: To reduce traffic accidents, a zero tolerance law is passed: "Driving with any trace of alcohol is strictly forbidden". | D90: core | E90: One night two drunk motorbikers race each other on a dark backroad. | F90: =LEN(E90) -> 67
A91: drin | B91: Drunk drivers pose a serious risk to other road users. | C91: To reduce traffic accidents, a zero tolerance law is passed: "Driving with any trace of alcohol is strictly forbidden". | D91: core | E91: A woman drives home after drinking whiskey at the movie theater. | F91: =LEN(E91) -> 64
A92: drin | B92: Drunk drivers pose a serious risk to other road users. | C92: To reduce traffic accidents, a zero tolerance law is passed: "Driving with any trace of alcohol is strictly forbidden". | D92: over | E92: A neighbor sips on wine and re-parks his car in the cul-de-sac. | F92: =LEN(E92) -> 63
A93: drin | B93: Drunk drivers pose a serious risk to other road users. | C93: To reduce traffic accidents, a zero tolerance law is passed: "Driving with any trace of alcohol is strictly forbidden". | D93: over | E93: A person drives to work after using alcohol-based mouthwash. | F93: =LEN(E93) -> 60
A94: drin | B94: Drunk drivers pose a serious risk to other road users. | C94: To reduce traffic accidents, a zero tolerance law is passed: "Driving with any trace of alcohol is strictly forbidden". | D94: over | E94: A drunk man drives his wife to the hospital as she goes into labor. | F94: =LEN(E94) -> 67
A95: drin | B95: Drunk drivers pose a serious risk to other road users. | C95: To reduce traffic accidents, a zero tolerance law is passed: "Driving with any trace of alcohol is strictly forbidden". | D95: under | E95: A young man rides his motorcycle home after smoking marihuana. | F95: =LEN(E95) -> 62
A96: drin | B96: Drunk drivers pose a serious risk to other road users. | C96: To reduce traffic accidents, a zero tolerance law is passed: "Driving with any trace of alcohol is strictly forbidden". | D96: under | E96: One stormy night two sober motorbikers race each other on a dark backroad. | F96: =LEN(E96) -> 74
A97: drin | B97: Drunk drivers pose a serious risk to other road users. | C97: To reduce traffic accidents, a zero tolerance law is passed: "Driving with any trace of alcohol is strictly forbidden". | D97: under | E97: A woman drives home after taking ecstasy at a music festival. | F97: =LEN(E97) -> 62
F100: mean | G100: sd
E101: overall | F101: =AVERAGE(F2:F97) -> 61.78125 | G101: =_xlfn.STDEV.S(F2:F85) -> 3.5887846 | H101: =AVERAGE(H2:H85) -> 0.47214286 | I101: =MEDIAN(I2:I85) -> 1526.5
E102: core | F102: =AVERAGE(F2:F4,F23:F25,F32:F34,F42:F44,F50:F52,F68:F70,F77:F79,F89:F91) -> 61.666667 | G102: =_xlfn.STDEV.S(F2:F4,F23:F25,F32:F34,F42:F44,F50:F52,F68:F70,F77:F79) -> 3.9623226 | H102: =AVERAGE(H2:H4,H23:H25,H32:H34,H42:H44,H50:H52,H68:H70,H77:H79) -> 0.92714286 | I102: =AVERAGE(I2:I4,I23:I25,I32:I34,I42:I44,I50:I52,I68:I70,I77:I79) -> 1307.1429
E103: off | F103: =AVERAGE(F11:F13,F20:F22,F29:F31,F38:F40,F59:F61,F65:F67,F75:F76,F86:F88) -> 61.304348 | G103: =_xlfn.STDEV.S(F11:F13,F20:F22,F29:F31,F38:F40,F59:F61,F65:F67) -> 2.812205 | H103: =AVERAGE(H11:H13,H20:H22,H29:H31,H38:H40,H59:H61,H65:H67,H74:H76) -> 0.073809524 | I103: =AVERAGE(I11:I13,I20:I22,I29:I31,I38:I40,I59:I61,I65:I67,I75:I76) -> 1694.1
E104: over | F104: =AVERAGE(F5:F7,F14:F16,F35:F37,F44:F46,F53:F55,F71:F73,F80:F82,F92:F94) -> 62.541667 | G104: =_xlfn.STDEV.S(F5:F7,F14:F16,F35:F37,F44:F46,F53:F55,F71:F73,F80:F82) -> 3.4579102 | H104: =AVERAGE(H5:H7,H14:H16,H35:H37,H44:H46,H53:H55,H71:H73,H80:H82) -> 0.51904762 | I104: =AVERAGE(I5:I7,I14:I16,I35:I37,I44:I46,I53:I55,I71:I73,I80:I82) -> 1618.619
E105: under | F105: =AVERAGE(F8:F10,F17:F19,F26:F28,F47:F49,F56:F58,F62:F64,F83:F85,F95:F97) -> 61.875 | G105: =_xlfn.STDEV.S(F8:F10,F17:F19,F26:F28,F47:F49,F56:F58,F62:F64,F83:F85) -> 4.0017853 | H105: =AVERAGE(H8:H10,H17:H19,H26:H28,H47:H49,H56:H58,H62:H64,H83:H85) -> 0.35809524 | I105: =AVERAGE(I8:I10,I17:I19,I26:I28,I47:I49,I56:I58,I62:I64,I83:I85) -> 1668.4286

Sheet Tabellenblatt2
A1: scen | B1: origin | C1: rule | D1: condition | E1: question | F1: character count
A2: shoe | B2: A friend entered Mary's house wearing shoes and dirtied the carpets. | C2: To keep her house clean, Mary established the rule: "No one may wear shoes in the house". | D2: core | E2: A guest wears stilettos and the carpets get pretty dirty. | F2: =LEN(E2) -> 57 | G2: L1
A3: shoe | B3: A friend entered Mary's house wearing shoes and dirtied the carpets. | C3: To keep her house clean, Mary established the rule: "No one may wear shoes in the house". | D3: core | E3: A guest wears wet deck shoes and dirties the floors. | F3: =LEN(E3) -> 52 | G3: L1
A4: shoe | B4: A friend entered Mary's house wearing shoes and dirtied the carpets. | C4: To keep her house clean, Mary established the rule: "No one may wear shoes in the house". | D4: core | E4: A guest wears muddy sneakers and dirties the carpets. | F4: =LEN(E4) -> 53 | G4: L1
A5: shoe | B5: A friend entered Mary's house wearing shoes and dirtied the carpets. | C5: To keep her house clean, Mary established the rule: "No one may wear shoes in the house". | D5: over | E5: A guest wears brand new shoes and keeps the floor clean. | F5: =LEN(E5) -> 56 | G5: L1c | H5: H1
A6: shoe | B6: A friend entered Mary's house wearing shoes and dirtied the carpets. | C6: To keep her house clean, Mary established the rule: "No one may wear shoes in the house". | D6: over | E6: A guest wears clean stilettos and keeps the carpet clean. | F6: =LEN(E6) -> 57 | H6: H1
A7: shoe | B7: A friend entered Mary's house wearing shoes and dirtied the carpets. | C7: To keep her house clean, Mary established the rule: "No one may wear shoes in the house". | D7: over | E7: A guest wears his new sneakers and the floor stays clean. | F7: =LEN(E7) -> 57 | H7: H1
A8: shoe | B8: A friend entered Mary's house wearing shoes and dirtied the carpets. | C8: To keep her house clean, Mary established the rule: "No one may wear shoes in the house". | D8: under | E8: A guest walks around barefoot and dirties the carpets. | F8: =LEN(E8) -> 54 | G8: L1c | H8: H1
A9: shoe | B9: A friend entered Mary's house wearing shoes and dirtied the carpets. | C9: To keep her house clean, Mary established the rule: "No one may wear shoes in the house". | D9: under | E9: A guest walks in with muddy socks and dirties the floor. | F9: =LEN(E9) -> 56 | H9: H1
A10: shoe | B10: A friend entered Mary's house wearing shoes and dirtied the carpets. | C10: To keep her house clean, Mary established the rule: "No one may wear shoes in the house". | D10: under | E10: A barefoot guest has a bleeding toe and stains the carpets. | F10: =LEN(E10) -> 59 | H10: H1
A11: shoe | B11: A friend entered Mary's house wearing shoes and dirtied the carpets. | C11: To keep her house clean, Mary established the rule: "No one may wear shoes in the house". | D11: off | E11: A guest walks around barefoot and keeps the carpet clean. | F11: =LEN(E11) -> 57 | G11: L1
A12: shoe | B12: A friend entered Mary's house wearing shoes and dirtied the carpets. | C12: To keep her house clean, Mary established the rule: "No one may wear shoes in the house". | D12: off | E12: A guest walks around in socks and keeps the floor clean. | F12: =LEN(E12) -> 56 | G12: L1
A13: shoe | B13: A friend entered Mary's house wearing shoes and dirtied the carpets. | C13: To keep her house clean, Mary established the rule: "No one may wear shoes in the house". | D13: off | E13: A guest walks around barefoot and the floor stays clean. | F13: =LEN(E13) -> 56 | G13: L1
A14: cars | B14: At the local park, a tragic accident took place involving a pedestrian and a car. | C14: To avoid accidents, the local authority issued a rule: "No cars are allowed inside the park". | D14: over | E14: An artist installs a race car in the park to honor local heroes. | F14: =LEN(E14) -> 64 | G14: L1
A15: cars | B15: At the local park, a tragic accident took place involving a pedestrian and a car. | C15: To avoid accidents, the local authority issued a rule: "No cars are allowed inside the park". | D15: over | E15: A landscaper parks a truck in the park to remove a tree. | F15: =LEN(E15) -> 56 | G15: L1
A16: cars | B16: At the local park, a tragic accident took place involving a pedestrian and a car. | C16: To avoid accidents, the local authority issued a rule: "No cars are allowed inside the park". | D16: over | E16: A man drives a tow-truck slowly into the park to remove a car. | F16: =LEN(E16) -> 62 | G16: L1
A17: cars | B17: At the local park, a tragic accident took place involving a pedestrian and a car. | C17: To avoid accidents, the local authority issued a rule: "No cars are allowed inside the park". | D17: under | E17: A person speeds through the park in their electric scooter. | F17: =LEN(E17) -> 59 | G17: L1c
A18: cars | B18: At the local park, a tragic accident took place involving a pedestrian and a car. | C18: To avoid accidents, the local authority issued a rule: "No cars are allowed inside the park". | D18: under | E18: A motorcycle courier takes a shortcut through the park. | F18: =LEN(E18) -> 55
A19: cars | B19: At the local park, a tragic accident took place involving a pedestrian and a car. | C19: To avoid accidents, the local authority issued a rule: "No cars are allowed inside the park". | D19: under | E19: A group of friends cycle through the park on a beer bike. | F19: =LEN(E19) -> 57
A20: cars | B20: At the local park, a tragic accident took place involving a pedestrian and a car. | C20: To avoid accidents, the local authority issued a rule: "No cars are allowed inside the park". | D20: off | E20: A person jogs through the park to get some daily exercise. | F20: =LEN(E20) -> 58 | G20: L1c
A21: cars | B21: At the local park, a tragic accident took place involving a pedestrian and a car. | C21: To avoid accidents, the local authority issued a rule: "No cars are allowed inside the park". | D21: off | E21: A couple walk their new baby through the park in a stroller. | F21: =LEN(E21) -> 60
A22: cars | B22: At the local park, a tragic accident took place involving a pedestrian and a car. | C22: To avoid accidents, the local authority issued a rule: "No cars are allowed inside the park". | D22: off | E22: A landscaper pushes a grey wheelbarrow through the park. | F22: =LEN(E22) -> 56
A23: cars | B23: At the local park, a tragic accident took place involving a pedestrian and a car. | C23: To avoid accidents, the local authority issued a rule: "No cars are allowed inside the park". | D23: core | E23: A person test-drives their new car through the park at noon. | F23: =LEN(E23) -> 60 | G23: L1
A24: cars | B24: At the local park, a tragic accident took place involving a pedestrian and a car. | C24: To avoid accidents, the local authority issued a rule: "No cars are allowed inside the park". | D24: core | E24: A taxi driver takes a shortcut through the park to save time. | F24: =LEN(E24) -> 61 | G24: L1
A25: cars | B25: At the local park, a tragic accident took place involving a pedestrian and a car. | C25: To avoid accidents, the local authority issued a rule: "No cars are allowed inside the park". | D25: core | E25: A red party limo drives through the park at the DJ's request. | F25: =LEN(E25) -> 61 | G25: L1
A26: slee | B26: A group of vagrants often slept on the benches of the local train station. | C26: To avoid people spending the night at the train station, the manager posted a rule: "No sleeping allowed on the benches". | D26: under | E26: A vagrant spends the whole night on a bench but does not sleep. | F26: =LEN(E26) -> 63 | G26: L1
A27: slee | B27: A group of vagrants often slept on the benches of the local train station. | C27: To avoid people spending the night at the train station, the manager posted a rule: "No sleeping allowed on the benches". | D27: under | E27: A vagrant spends the night sleeping on the station floor. | F27: =LEN(E27) -> 57 | G27: L1
A28: slee | B28: A group of vagrants often slept on the benches of the local train station. | C28: To avoid people spending the night at the train station, the manager posted a rule: "No sleeping allowed on the benches". | D28: under | E28: A backpacker spends the night sleeping behind a station bench. | F28: =LEN(E28) -> 62 | G28: L1
A29: slee | B29: A group of vagrants often slept on the benches of the local train station. | C29: To avoid people spending the night at the train station, the manager posted a rule: "No sleeping allowed on the benches". | D29: off | E29: A businesswoman enters the station and buys her train ticket. | F29: =LEN(E29) -> 61 | G29: L1c
A30: slee | B30: A group of vagrants often slept on the benches of the local train station. | C30: To avoid people spending the night at the train station, the manager posted a rule: "No sleeping allowed on the benches". | D30: off | E30: A commuter sits on a station bench while waiting for her train. | F30: =LEN(E30) -> 63
A31: slee | B31: A group of vagrants often slept on the benches of the local train station. | C31: To avoid people spending the night at the train station, the manager posted a rule: "No sleeping allowed on the benches". | D31: off | E31: A backpacker looks for her lost phone on the station platform. | F31: =LEN(E31) -> 62
A32: slee | B32: A group of vagrants often slept on the benches of the local train station. | C32: To avoid people spending the night at the train station, the manager posted a rule: "No sleeping allowed on the benches". | D32: core | E32: A vagrant spends the night sleeping on a bench at the station. | F32: =LEN(E32) -> 62 | G32: L1c
A33: slee | B33: A group of vagrants often slept on the benches of the local train station. | C33: To avoid people spending the night at the train station, the manager posted a rule: "No sleeping allowed on the benches". | D33: core | E33: A backpacker spends the night sleeping on a station bench. | F33: =LEN(E33) -> 58
A34: slee | B34: A group of vagrants often slept on the benches of the local train station. | C34: To avoid people spending the night at the train station, the manager posted a rule: "No sleeping allowed on the benches". | D34: core | E34: A nightclub dancer falls asleep on a station bench after work. | F34: =LEN(E34) -> 62
A35: slee | B35: A group of vagrants often slept on the benches of the local train station. | C35: To avoid people spending the night at the train station, the manager posted a rule: "No sleeping allowed on the benches". | D35: over | E35: A commuter briefly falls asleep on a bench waiting for his train. | F35: =LEN(E35) -> 65 | G35: L1
A36: slee | B36: A group of vagrants often slept on the benches of the local train station. | C36: To avoid people spending the night at the train station, the manager posted a rule: "No sleeping allowed on the benches". | D36: over | E36: A backpacker sits on a station bench and takes a five-minute nap. | F36: =LEN(E36) -> 65 | G36: L1
A37: slee | B37: A group of vagrants often slept on the benches of the local train station. | C37: To avoid people spending the night at the train station, the manager posted a rule: "No sleeping allowed on the benches". | D37: over | E37: A shift worker briefly dozes on a bench waiting for her manager. | F37: =LEN(E37) -> 64 | G37: L1
A38: phon | B38: Classes at a local school were frequently disrupted by students using their phones. | C38: To get students to pay attention in class, the headmaster announced: "Phones may not be used in the classroom". | D38: off | E38: A student consults the textbook to answer a question in class. | F38: =LEN(E38) -> 62 | G38: L1
A39: phon | B39: Classes at a local school were frequently disrupted by students using their phones. | C39: To get students to pay attention in class, the headmaster announced: "Phones may not be used in the classroom". | D39: off | E39: A student takes notes by hand to help her understand a lesson. | F39: =LEN(E39) -> 62 | G39: L1
A40: phon | B40: Classes at a local school were frequently disrupted by students using their phones. | C40: To get students to pay attention in class, the headmaster announced: "Phones may not be used in the classroom". | D40: off | E40: A student arrives early to class and takes out her pencil case. | F40: =LEN(E40) -> 63 | G40: L1
...

Sheet Tabellenblatt1
A1: scen | B1: Type | C1: Item | D1: mean(resp, na.rm = TRUE) | E1: median(as.double(Timing), na.rm = TRUE)
A2: Access | B2: core | C2: A member of the public enters the laboratory to see great scientists at work. | D2: 818181818 | E2: 1738
A3: Access | B3: core | C3: A thief enters the laboratory to find valuable scientific equipment to steal. | D3: 909090909 | E3: 1597
A4: Access | B4: core | C4: A tourist enters the laboratory to get a glimpse of great scientists at work. | D4: 823529412 | E4: 1401
A5: Access | B5: off | C5: A member of the public walks past the laboratory on her way to the park. | D5: 1875 | E5: 1422622
A6: Access | B6: off | C6: A scientist working at the laboratory gets started on her latest experiment. | D6: 153846154 | E6: 1191
A7: Access | B7: off | C7: A tourist walks past the laboratory on his way to the new science museum. | D7: 166666667 | E7: 1298
A8: Access | B8: over | C8: A recently retired scientist at the laboratory returns to collect his briefcase. | D8: 625 | E8: 1484
A9: Access | B9: over | C9: A recently retired scientist at the laboratory returns to offer some advice. | D9: 352941176 | E9: 1768
A10: Access | B10: over | C10: A scientist at a similar institution enters the lab to ask about a job vacancy. | D10: 222222222 | E10: 1618
A11: Access | B11: under | C11: A scientist at the laboratory spends the night sleeping on fragile equipment | D11: 0.4 | E11: 1663
A12: Access | B12: under | C12: A scientist at the laboratory stays on after work and gets very drunk there. | D12: 230769231 | E12: 1535
A13: Access | B13: under | C13: A scientist at the laboratory stays on after work and takes hard drugs there. | D13: 583333333 | E13: 1156026
A14: Cars | B14: core | C14: A person test-drives their new car through the park at noon. | D14: 1 | E14: 1113
A15: Cars | B15: core | C15: A red party limo drives through the park at the DJs request. | D15: 1 | E15: 1043
A16: Cars | B16: core | C16: A taxi driver takes a shortcut through the park to save time. | D16: 916666667 | E16: 597173
A17: Cars | B17: off | C17: A couple bring their new baby through the park in a sling. | D17: 0 | E17: 1569
A18: Cars | B18: off | C18: A landscaper pushes a grey wheelbarrow through the park. | D18: 176470588 | E18: 1269
A19: Cars | B19: off | C19: A person jogs through the park to get some daily exercise. | D19: 0 | E19: 1518
A20: Cars | B20: over | C20: A man drives a tow-truck slowly into the park to remove a car. | D20: 333333333 | E20: 677558
A21: Cars | B21: over | C21: A man parks a landscaper truck in the park to remove a tree. | D21: 375 | E21: 1426274
A22: Cars | B22: over | C22: An artist installs a race car in the park to honour local heroes. | D22: 384615385 | E22: 1351
A23: Cars | B23: under | C23: A group of friends cycle through the park on a beer bike. | D23: 117647059 | E23: 1.94
A24: Cars | B24: under | C24: A motorcycle courier takes a shortcut through the park. | D24: 454545455 | E24: 1803
A25: Cars | B25: under | C25: A person test-drives their new electric scooter in the park. | D25: 90909091 | E25: 1204
A26: Dogs | B26: core | C26: A couple bring their pet foxhound into the restaurant for dinner. | D26: 9375 | E26: 1267
A27: Dogs | B27: core | C27: A customer brings her pet bulldog into the restaurant for lunch. | D27: 923076923 | E27: 1248
A28: Dogs | B28: core | C28: A customer walks into the restaurant with his pet greyhound. | D28: 1 | E28: 8675
A29: Dogs | B29: off | C29: A couple have breakfast together at the restaurant before work. | D29: 83333333 | E29: 2423386
A30: Dogs | B30: off | C30: A customer uses the restaurant WC while waiting for her food. | D30: 0 | E30: 1349
A31: Dogs | B31: off | C31: Three colleagues have a meeting over dinner at the restaurant. | D31: 0 | E31: 1926
A32: Dogs | B32: over | C32: A blind person brings his trained guide dog into the restaurant. | D32: 0 | E32: 1662
A33: Dogs | B33: over | C33: A man carries an injured dog into the restaurant to call for help. | D33: 411764706 | E33: 1846
A34: Dogs | B34: over | C34: A woman brings her trained therapy labrador into the restaurant. | D34: 636363636 | E34: 1639
A35: Dogs | B35: under | C35: A customer brings his new pet fox into the restaurant for lunch. | D35: 4375 | E35: 1488
... A42: Phone | B42: off | C42: A student consults the textbook to answer the teachers question in class. | D42: 0 | E42: 1516
A43: Phone | B43: off | C43: A student takes thorough notes to help her understand her teachers lesson. | D43: 625 | E43: 2.1575
A44: Phone | B44: over | C44: A diabetic student responds to an alert on her phone to take an insulin shot. | D44: 4375 | E44: 1324006
A45: Phone | B45: over | C45: A student uses her phone as a paperweight to keep her papers together. | D45: 705882353 | E45: 1394
A46: Phone | B46: over | C46: A student uses his phones calculator function for the in-class assignment. | D46: 777777778 | E46: 1.61
...

Sheet varying proportions
A1: scen | B1: rule | C1: condition | D1: question | E1: character count
A2: auth | B2: To avoid accidents, the director of a scientific laboratory issued a rule: "Access for Laboratory Personnel Only". | C2: core | D2: A thief enters the laboratory overnight to find and steal equipment. | E2: =LEN(D2) -> 68
A3: auth | B3: To avoid accidents, the director of a scientific laboratory issued a rule: "Access for Laboratory Personnel Only". | C3: core | D3: A friendly neighbor enters the laboratory to greet the scientists. | E3: =LEN(D3) -> 66
A4: auth | B4: To avoid accidents, the director of a scientific laboratory issued a rule: "Access for Laboratory Personnel Only". | C4: core | D4: A student enters the laboratory to observe the scientists' work. | E4: =LEN(D4) -> 64
A5: auth | B5: To avoid accidents, the director of a scientific laboratory issued a rule: "Access for Laboratory Personnel Only". | C5: core | D5: An amateur scientist enters the laboratory to take photographs. | E5: =LEN(D5) -> 63
A6: auth | B6: To avoid accidents, the director of a scientific laboratory issued a rule: "Access for Laboratory Personnel Only". | C6: core | D6: A group of solicitors enter the laboratory to discuss religion. | E6: =LEN(D6) -> 63
A7: auth | B7: To avoid accidents, the director of a scientific laboratory issued a rule: "Access for Laboratory Personnel Only". | C7: off | D7: A member of the public walks past the laboratory while going home. | E7: =LEN(D7) -> 66
A8: auth | B8: To avoid accidents, the director of a scientific laboratory issued a rule: "Access for Laboratory Personnel Only". | C8: off | D8: A tourist walks past the laboratory on his way to the wax museum. | E8: =LEN(D8) -> 65
A9: auth | B9: To avoid accidents, the director of a scientific laboratory issued a rule: "Access for Laboratory Personnel Only". | C9: off | D9: A curious neighbor photographs the lab building from the outside. | E9: =LEN(D9) -> 65
A10: auth | B10: To avoid accidents, the director of a scientific laboratory issued a rule: "Access for Laboratory Personnel Only". | C10: off | D10: A scientist working at the laboratory starts a new experiment. | E10: =LEN(D10) -> 62
A11: auth | B11: To avoid accidents, the director of a scientific laboratory issued a rule: "Access for Laboratory Personnel Only". | C11: off | D11: A solicitor discusses religion across the street from the lab. | E11: =LEN(D11) -> 62
A12: auth | B12: To avoid accidents, the director of a scientific laboratory issued a rule: "Access for Laboratory Personnel Only". | C12: over | D12: A retired scientist visits the lab to offer advice to new hirees. | E12: =LEN(D12) -> 65
A13: auth | B13: To avoid accidents, the director of a scientific laboratory issued a rule: "Access for Laboratory Personnel Only". | C13: over | D13: A firefighter enters the lab to put out an impending fire. | E13: =LEN(D13) -> 58
... A161: slee | B161: To avoid people spending the night at the train station, the manager posted a rule: "No sleeping allowed on the benches". | C161: under | D161: A vagrant spends the night sleeping on the station floor. | E161: =LEN(D161) -> 57

Sheet Tabellenblatt4
C1: mean | D1: sd
B2: core | C2: =AVERAGE('varying proportions'!E2:E6,'varying proportions'!E22:E26,'varying proportions'!E42:E46,'varying proportions'!E62:E66,'varying proportions'!E82:E86,'varying proportions'!E102:E106,'varying proportions'!E122:E126,'varying proportions'!E142:E146) -> 61.125 | D2: =STDEV('varying proportions'!E2:E6,'varying proportions'!E22:E26,'varying proportions'!E42:E46,'varying proportions'!E62:E66,'varying proportions'!E82:E86,'varying proportions'!E102:E106,'varying proportions'!E122:E126,'varying proportions'!E142:E146) -> 4.5752259
B3: off | C3: =AVERAGE('varying proportions'!E7:E11,'varying proportions'!E27:E31,'varying proportions'!E47:E51,'varying proportions'!E67:E71,'varying proportions'!E87:E91,'varying proportions'!E107:E111,'varying proportions'!E127:E131,'varying proportions'!E147:E151) -> 61.2 | D3: =STDEV('varying proportions'!E7:E11,'varying proportions'!E27:E31,'varying proportions'!E47:E51,'varying proportions'!E67:E71,'varying proportions'!E87:E91,'varying proportions'!E107:E111,'varying proportions'!E127:E131,'varying proportions'!E147:E151) -> 3.3832165
B4: over | C4: =AVERAGE('varying proportions'!E12:E16,'varying proportions'!E32:E36,'varying proportions'!E52:E56,'varying proportions'!E72:E76,'varying proportions'!E92:E96,'varying proportions'!E112:E116,'varying proportions'!E132:E136,'varying proportions'!E152:E156) -> 61.425 | D4: =STDEV('varying proportions'!E12:E16,'varying proportions'!E32:E36,'varying proportions'!E52:E56,'varying proportions'!E72:E76,'varying proportions'!E92:E96,'varying proportions'!E112:E116,'varying proportions'!E132:E136,'varying proportions'!E152:E156) -> 3.7271526
B5: under | C5: =AVERAGE('varying proportions'!E17:E21,'varying proportions'!E37:E41,'varying proportions'!E57:E61,'varying proportions'!E77:E81,'varying proportions'!E97:E101,'varying proportions'!E117:E121,'varying proportions'!E137:E141,'varying proportions'!E157:E161) -> 61.225 | D5: =STDEV('varying proportions'!E17:E21,'varying proportions'!E37:E41,'varying proportions'!E57:E61,'varying proportions'!E77:E81,'varying proportions'!E97:E101,'varying proportions'!E117:E121,'varying proportions'!E137:E141,'varying proportions'!E157:E161) -> 4.2152805
